INFO       - 2024-09-13 18:16:50 - client          : logging in using static token
INFO       - 2024-09-13 18:16:52 - gateway         : Shard ID None has connected to Gateway (Session ID: fdbced5105e520c72bf01fd827613c41).
ERROR      - 2024-09-13 18:17:54 - bot             : Ignoring exception in command trophy
Traceback (most recent call last):
  File "/home/abc/Desktop/Coding/Python/Discord Bot/Skybot/.venv/lib/python3.12/site-packages/urllib3/connectionpool.py", line 466, in _make_request
    self._validate_conn(conn)
  File "/home/abc/Desktop/Coding/Python/Discord Bot/Skybot/.venv/lib/python3.12/site-packages/urllib3/connectionpool.py", line 1095, in _validate_conn
    conn.connect()
  File "/home/abc/Desktop/Coding/Python/Discord Bot/Skybot/.venv/lib/python3.12/site-packages/urllib3/connection.py", line 652, in connect
    sock_and_verified = _ssl_wrap_socket_and_match_hostname(
                        ^^^^^^^^^^^^^^^^^^^^^^^^^^^^^^^^^^^^
  File "/home/abc/Desktop/Coding/Python/Discord Bot/Skybot/.venv/lib/python3.12/site-packages/urllib3/connection.py", line 805, in _ssl_wrap_socket_and_match_hostname
    ssl_sock = ssl_wrap_socket(
               ^^^^^^^^^^^^^^^^
  File "/home/abc/Desktop/Coding/Python/Discord Bot/Skybot/.venv/lib/python3.12/site-packages/urllib3/util/ssl_.py", line 465, in ssl_wrap_socket
    ssl_sock = _ssl_wrap_socket_impl(sock, context, tls_in_tls, server_hostname)
               ^^^^^^^^^^^^^^^^^^^^^^^^^^^^^^^^^^^^^^^^^^^^^^^^^^^^^^^^^^^^^^^^^
  File "/home/abc/Desktop/Coding/Python/Discord Bot/Skybot/.venv/lib/python3.12/site-packages/urllib3/util/ssl_.py", line 509, in _ssl_wrap_socket_impl
    return ssl_context.wrap_socket(sock, server_hostname=server_hostname)
           ^^^^^^^^^^^^^^^^^^^^^^^^^^^^^^^^^^^^^^^^^^^^^^^^^^^^^^^^^^^^^^
  File "/usr/local/lib/python3.12/ssl.py", line 455, in wrap_socket
    return self.sslsocket_class._create(
           ^^^^^^^^^^^^^^^^^^^^^^^^^^^^^
  File "/usr/local/lib/python3.12/ssl.py", line 1042, in _create
    self.do_handshake()
  File "/usr/local/lib/python3.12/ssl.py", line 1320, in do_handshake
    self._sslobj.do_handshake()
ssl.SSLCertVerificationError: [SSL: CERTIFICATE_VERIFY_FAILED] certificate verify failed: self-signed certificate in certificate chain (_ssl.c:1000)

During handling of the above exception, another exception occurred:

Traceback (most recent call last):
  File "/home/abc/Desktop/Coding/Python/Discord Bot/Skybot/.venv/lib/python3.12/site-packages/urllib3/connectionpool.py", line 789, in urlopen
    response = self._make_request(
               ^^^^^^^^^^^^^^^^^^^
  File "/home/abc/Desktop/Coding/Python/Discord Bot/Skybot/.venv/lib/python3.12/site-packages/urllib3/connectionpool.py", line 490, in _make_request
    raise new_e
urllib3.exceptions.SSLError: [SSL: CERTIFICATE_VERIFY_FAILED] certificate verify failed: self-signed certificate in certificate chain (_ssl.c:1000)

The above exception was the direct cause of the following exception:

Traceback (most recent call last):
  File "/home/abc/Desktop/Coding/Python/Discord Bot/Skybot/.venv/lib/python3.12/site-packages/requests/adapters.py", line 667, in send
    resp = conn.urlopen(
           ^^^^^^^^^^^^^
  File "/home/abc/Desktop/Coding/Python/Discord Bot/Skybot/.venv/lib/python3.12/site-packages/urllib3/connectionpool.py", line 843, in urlopen
    retries = retries.increment(
              ^^^^^^^^^^^^^^^^^^
  File "/home/abc/Desktop/Coding/Python/Discord Bot/Skybot/.venv/lib/python3.12/site-packages/urllib3/util/retry.py", line 519, in increment
    raise MaxRetryError(_pool, url, reason) from reason  # type: ignore[arg-type]
    ^^^^^^^^^^^^^^^^^^^^^^^^^^^^^^^^^^^^^^^^^^^^^^^^^^^
urllib3.exceptions.MaxRetryError: HTTPSConnectionPool(host='api.mojang.com', port=443): Max retries exceeded with url: /users/profiles/minecraft/L3Xtor (Caused by SSLError(SSLCertVerificationError(1, '[SSL: CERTIFICATE_VERIFY_FAILED] certificate verify failed: self-signed certificate in certificate chain (_ssl.c:1000)')))

During handling of the above exception, another exception occurred:

Traceback (most recent call last):
  File "/home/abc/Desktop/Coding/Python/Discord Bot/Skybot/.venv/lib/python3.12/site-packages/discord/app_commands/commands.py", line 857, in _do_call
    return await self._callback(self.binding, interaction, **params)  # type: ignore
           ^^^^^^^^^^^^^^^^^^^^^^^^^^^^^^^^^^^^^^^^^^^^^^^^^^^^^^^^^
  File "/home/abc/Desktop/Coding/Python/Discord Bot/Skybot/hypixel/Fishing.py", line 15, in trophy
    PID, selectedprofile = returnProfileID(selectedprofile=selectedprofile, playername=playername)
                           ^^^^^^^^^^^^^^^^^^^^^^^^^^^^^^^^^^^^^^^^^^^^^^^^^^^^^^^^^^^^^^^^^^^^^^^
  File "/home/abc/Desktop/Coding/Python/Discord Bot/Skybot/hypixel/Catacombs.py", line 64, in returnProfileID
    hypixelProfiles = miscellaneous_data(playername=playername)
                      ^^^^^^^^^^^^^^^^^^^^^^^^^^^^^^^^^^^^^^^^^
  File "/home/abc/Desktop/Coding/Python/Discord Bot/Skybot/hypixel/Catacombs.py", line 52, in miscellaneous_data
    mojangData = requests.get('https://api.mojang.com/users/profiles/minecraft/' + playername).json()
                 ^^^^^^^^^^^^^^^^^^^^^^^^^^^^^^^^^^^^^^^^^^^^^^^^^^^^^^^^^^^^^^^^^^^^^^^^^^^^^
  File "/home/abc/Desktop/Coding/Python/Discord Bot/Skybot/.venv/lib/python3.12/site-packages/requests/api.py", line 73, in get
    return request("get", url, params=params, **kwargs)
           ^^^^^^^^^^^^^^^^^^^^^^^^^^^^^^^^^^^^^^^^^^^^
  File "/home/abc/Desktop/Coding/Python/Discord Bot/Skybot/.venv/lib/python3.12/site-packages/requests/api.py", line 59, in request
    return session.request(method=method, url=url, **kwargs)
           ^^^^^^^^^^^^^^^^^^^^^^^^^^^^^^^^^^^^^^^^^^^^^^^^^
  File "/home/abc/Desktop/Coding/Python/Discord Bot/Skybot/.venv/lib/python3.12/site-packages/requests/sessions.py", line 589, in request
    resp = self.send(prep, **send_kwargs)
           ^^^^^^^^^^^^^^^^^^^^^^^^^^^^^^
  File "/home/abc/Desktop/Coding/Python/Discord Bot/Skybot/.venv/lib/python3.12/site-packages/requests/sessions.py", line 703, in send
    r = adapter.send(request, **kwargs)
        ^^^^^^^^^^^^^^^^^^^^^^^^^^^^^^^
  File "/home/abc/Desktop/Coding/Python/Discord Bot/Skybot/.venv/lib/python3.12/site-packages/requests/adapters.py", line 698, in send
    raise SSLError(e, request=request)
requests.exceptions.SSLError: HTTPSConnectionPool(host='api.mojang.com', port=443): Max retries exceeded with url: /users/profiles/minecraft/L3Xtor (Caused by SSLError(SSLCertVerificationError(1, '[SSL: CERTIFICATE_VERIFY_FAILED] certificate verify failed: self-signed certificate in certificate chain (_ssl.c:1000)')))

The above exception was the direct cause of the following exception:

Traceback (most recent call last):
  File "/home/abc/Desktop/Coding/Python/Discord Bot/Skybot/.venv/lib/python3.12/site-packages/discord/ext/commands/hybrid.py", line 444, in _invoke_with_namespace
    value = await self._do_call(ctx, ctx.kwargs)  # type: ignore
            ^^^^^^^^^^^^^^^^^^^^^^^^^^^^^^^^^^^^
  File "/home/abc/Desktop/Coding/Python/Discord Bot/Skybot/.venv/lib/python3.12/site-packages/discord/app_commands/commands.py", line 876, in _do_call
    raise CommandInvokeError(self, e) from e
discord.app_commands.errors.CommandInvokeError: Command 'trophy' raised an exception: SSLError: HTTPSConnectionPool(host='api.mojang.com', port=443): Max retries exceeded with url: /users/profiles/minecraft/L3Xtor (Caused by SSLError(SSLCertVerificationError(1, '[SSL: CERTIFICATE_VERIFY_FAILED] certificate verify failed: self-signed certificate in certificate chain (_ssl.c:1000)')))

The above exception was the direct cause of the following exception:

Traceback (most recent call last):
  File "/home/abc/Desktop/Coding/Python/Discord Bot/Skybot/.venv/lib/python3.12/site-packages/discord/ext/commands/hybrid.py", line 444, in _invoke_with_namespace
    value = await self._do_call(ctx, ctx.kwargs)  # type: ignore
            ^^^^^^^^^^^^^^^^^^^^^^^^^^^^^^^^^^^^
  File "/home/abc/Desktop/Coding/Python/Discord Bot/Skybot/.venv/lib/python3.12/site-packages/discord/app_commands/commands.py", line 876, in _do_call
    raise CommandInvokeError(self, e) from e
discord.ext.commands.errors.HybridCommandError: Hybrid command raised an error: Command 'trophy' raised an exception: SSLError: HTTPSConnectionPool(host='api.mojang.com', port=443): Max retries exceeded with url: /users/profiles/minecraft/L3Xtor (Caused by SSLError(SSLCertVerificationError(1, '[SSL: CERTIFICATE_VERIFY_FAILED] certificate verify failed: self-signed certificate in certificate chain (_ssl.c:1000)')))
ERROR      - 2024-09-13 18:18:21 - bot             : Ignoring exception in command trophy
Traceback (most recent call last):
  File "/home/abc/Desktop/Coding/Python/Discord Bot/Skybot/.venv/lib/python3.12/site-packages/urllib3/connectionpool.py", line 466, in _make_request
    self._validate_conn(conn)
  File "/home/abc/Desktop/Coding/Python/Discord Bot/Skybot/.venv/lib/python3.12/site-packages/urllib3/connectionpool.py", line 1095, in _validate_conn
    conn.connect()
  File "/home/abc/Desktop/Coding/Python/Discord Bot/Skybot/.venv/lib/python3.12/site-packages/urllib3/connection.py", line 652, in connect
    sock_and_verified = _ssl_wrap_socket_and_match_hostname(
                        ^^^^^^^^^^^^^^^^^^^^^^^^^^^^^^^^^^^^
  File "/home/abc/Desktop/Coding/Python/Discord Bot/Skybot/.venv/lib/python3.12/site-packages/urllib3/connection.py", line 805, in _ssl_wrap_socket_and_match_hostname
    ssl_sock = ssl_wrap_socket(
               ^^^^^^^^^^^^^^^^
  File "/home/abc/Desktop/Coding/Python/Discord Bot/Skybot/.venv/lib/python3.12/site-packages/urllib3/util/ssl_.py", line 465, in ssl_wrap_socket
    ssl_sock = _ssl_wrap_socket_impl(sock, context, tls_in_tls, server_hostname)
               ^^^^^^^^^^^^^^^^^^^^^^^^^^^^^^^^^^^^^^^^^^^^^^^^^^^^^^^^^^^^^^^^^
  File "/home/abc/Desktop/Coding/Python/Discord Bot/Skybot/.venv/lib/python3.12/site-packages/urllib3/util/ssl_.py", line 509, in _ssl_wrap_socket_impl
    return ssl_context.wrap_socket(sock, server_hostname=server_hostname)
           ^^^^^^^^^^^^^^^^^^^^^^^^^^^^^^^^^^^^^^^^^^^^^^^^^^^^^^^^^^^^^^
  File "/usr/local/lib/python3.12/ssl.py", line 455, in wrap_socket
    return self.sslsocket_class._create(
           ^^^^^^^^^^^^^^^^^^^^^^^^^^^^^
  File "/usr/local/lib/python3.12/ssl.py", line 1042, in _create
    self.do_handshake()
  File "/usr/local/lib/python3.12/ssl.py", line 1320, in do_handshake
    self._sslobj.do_handshake()
ssl.SSLCertVerificationError: [SSL: CERTIFICATE_VERIFY_FAILED] certificate verify failed: self-signed certificate in certificate chain (_ssl.c:1000)

During handling of the above exception, another exception occurred:

Traceback (most recent call last):
  File "/home/abc/Desktop/Coding/Python/Discord Bot/Skybot/.venv/lib/python3.12/site-packages/urllib3/connectionpool.py", line 789, in urlopen
    response = self._make_request(
               ^^^^^^^^^^^^^^^^^^^
  File "/home/abc/Desktop/Coding/Python/Discord Bot/Skybot/.venv/lib/python3.12/site-packages/urllib3/connectionpool.py", line 490, in _make_request
    raise new_e
urllib3.exceptions.SSLError: [SSL: CERTIFICATE_VERIFY_FAILED] certificate verify failed: self-signed certificate in certificate chain (_ssl.c:1000)

The above exception was the direct cause of the following exception:

Traceback (most recent call last):
  File "/home/abc/Desktop/Coding/Python/Discord Bot/Skybot/.venv/lib/python3.12/site-packages/requests/adapters.py", line 667, in send
    resp = conn.urlopen(
           ^^^^^^^^^^^^^
  File "/home/abc/Desktop/Coding/Python/Discord Bot/Skybot/.venv/lib/python3.12/site-packages/urllib3/connectionpool.py", line 843, in urlopen
    retries = retries.increment(
              ^^^^^^^^^^^^^^^^^^
  File "/home/abc/Desktop/Coding/Python/Discord Bot/Skybot/.venv/lib/python3.12/site-packages/urllib3/util/retry.py", line 519, in increment
    raise MaxRetryError(_pool, url, reason) from reason  # type: ignore[arg-type]
    ^^^^^^^^^^^^^^^^^^^^^^^^^^^^^^^^^^^^^^^^^^^^^^^^^^^
urllib3.exceptions.MaxRetryError: HTTPSConnectionPool(host='api.mojang.com', port=443): Max retries exceeded with url: /users/profiles/minecraft/L3xtor (Caused by SSLError(SSLCertVerificationError(1, '[SSL: CERTIFICATE_VERIFY_FAILED] certificate verify failed: self-signed certificate in certificate chain (_ssl.c:1000)')))

During handling of the above exception, another exception occurred:

Traceback (most recent call last):
  File "/home/abc/Desktop/Coding/Python/Discord Bot/Skybot/.venv/lib/python3.12/site-packages/discord/app_commands/commands.py", line 857, in _do_call
    return await self._callback(self.binding, interaction, **params)  # type: ignore
           ^^^^^^^^^^^^^^^^^^^^^^^^^^^^^^^^^^^^^^^^^^^^^^^^^^^^^^^^^
  File "/home/abc/Desktop/Coding/Python/Discord Bot/Skybot/hypixel/Fishing.py", line 15, in trophy
    PID, selectedprofile = returnProfileID(selectedprofile=selectedprofile, playername=playername)
                           ^^^^^^^^^^^^^^^^^^^^^^^^^^^^^^^^^^^^^^^^^^^^^^^^^^^^^^^^^^^^^^^^^^^^^^^
  File "/home/abc/Desktop/Coding/Python/Discord Bot/Skybot/hypixel/Catacombs.py", line 64, in returnProfileID
    hypixelProfiles = miscellaneous_data(playername=playername)
                      ^^^^^^^^^^^^^^^^^^^^^^^^^^^^^^^^^^^^^^^^^
  File "/home/abc/Desktop/Coding/Python/Discord Bot/Skybot/hypixel/Catacombs.py", line 52, in miscellaneous_data
    mojangData = requests.get('https://api.mojang.com/users/profiles/minecraft/' + playername).json()
                 ^^^^^^^^^^^^^^^^^^^^^^^^^^^^^^^^^^^^^^^^^^^^^^^^^^^^^^^^^^^^^^^^^^^^^^^^^^^^^
  File "/home/abc/Desktop/Coding/Python/Discord Bot/Skybot/.venv/lib/python3.12/site-packages/requests/api.py", line 73, in get
    return request("get", url, params=params, **kwargs)
           ^^^^^^^^^^^^^^^^^^^^^^^^^^^^^^^^^^^^^^^^^^^^
  File "/home/abc/Desktop/Coding/Python/Discord Bot/Skybot/.venv/lib/python3.12/site-packages/requests/api.py", line 59, in request
    return session.request(method=method, url=url, **kwargs)
           ^^^^^^^^^^^^^^^^^^^^^^^^^^^^^^^^^^^^^^^^^^^^^^^^^
  File "/home/abc/Desktop/Coding/Python/Discord Bot/Skybot/.venv/lib/python3.12/site-packages/requests/sessions.py", line 589, in request
    resp = self.send(prep, **send_kwargs)
           ^^^^^^^^^^^^^^^^^^^^^^^^^^^^^^
  File "/home/abc/Desktop/Coding/Python/Discord Bot/Skybot/.venv/lib/python3.12/site-packages/requests/sessions.py", line 703, in send
    r = adapter.send(request, **kwargs)
        ^^^^^^^^^^^^^^^^^^^^^^^^^^^^^^^
  File "/home/abc/Desktop/Coding/Python/Discord Bot/Skybot/.venv/lib/python3.12/site-packages/requests/adapters.py", line 698, in send
    raise SSLError(e, request=request)
requests.exceptions.SSLError: HTTPSConnectionPool(host='api.mojang.com', port=443): Max retries exceeded with url: /users/profiles/minecraft/L3xtor (Caused by SSLError(SSLCertVerificationError(1, '[SSL: CERTIFICATE_VERIFY_FAILED] certificate verify failed: self-signed certificate in certificate chain (_ssl.c:1000)')))

The above exception was the direct cause of the following exception:

Traceback (most recent call last):
  File "/home/abc/Desktop/Coding/Python/Discord Bot/Skybot/.venv/lib/python3.12/site-packages/discord/ext/commands/hybrid.py", line 444, in _invoke_with_namespace
    value = await self._do_call(ctx, ctx.kwargs)  # type: ignore
            ^^^^^^^^^^^^^^^^^^^^^^^^^^^^^^^^^^^^
  File "/home/abc/Desktop/Coding/Python/Discord Bot/Skybot/.venv/lib/python3.12/site-packages/discord/app_commands/commands.py", line 876, in _do_call
    raise CommandInvokeError(self, e) from e
discord.app_commands.errors.CommandInvokeError: Command 'trophy' raised an exception: SSLError: HTTPSConnectionPool(host='api.mojang.com', port=443): Max retries exceeded with url: /users/profiles/minecraft/L3xtor (Caused by SSLError(SSLCertVerificationError(1, '[SSL: CERTIFICATE_VERIFY_FAILED] certificate verify failed: self-signed certificate in certificate chain (_ssl.c:1000)')))

The above exception was the direct cause of the following exception:

Traceback (most recent call last):
  File "/home/abc/Desktop/Coding/Python/Discord Bot/Skybot/.venv/lib/python3.12/site-packages/discord/ext/commands/hybrid.py", line 444, in _invoke_with_namespace
    value = await self._do_call(ctx, ctx.kwargs)  # type: ignore
            ^^^^^^^^^^^^^^^^^^^^^^^^^^^^^^^^^^^^
  File "/home/abc/Desktop/Coding/Python/Discord Bot/Skybot/.venv/lib/python3.12/site-packages/discord/app_commands/commands.py", line 876, in _do_call
    raise CommandInvokeError(self, e) from e
discord.ext.commands.errors.HybridCommandError: Hybrid command raised an error: Command 'trophy' raised an exception: SSLError: HTTPSConnectionPool(host='api.mojang.com', port=443): Max retries exceeded with url: /users/profiles/minecraft/L3xtor (Caused by SSLError(SSLCertVerificationError(1, '[SSL: CERTIFICATE_VERIFY_FAILED] certificate verify failed: self-signed certificate in certificate chain (_ssl.c:1000)')))
ERROR      - 2024-09-13 18:20:34 - bot             : Ignoring exception in command rank
Traceback (most recent call last):
  File "/home/abc/Desktop/Coding/Python/Discord Bot/Skybot/.venv/lib/python3.12/site-packages/discord/app_commands/commands.py", line 857, in _do_call
    return await self._callback(self.binding, interaction, **params)  # type: ignore
           ^^^^^^^^^^^^^^^^^^^^^^^^^^^^^^^^^^^^^^^^^^^^^^^^^^^^^^^^^
  File "/home/abc/Desktop/Coding/Python/Discord Bot/Skybot/cogs/Level.py", line 141, in rank
    cursor.execute(f"""
sqlite3.OperationalError: no such column: level

The above exception was the direct cause of the following exception:

Traceback (most recent call last):
  File "/home/abc/Desktop/Coding/Python/Discord Bot/Skybot/.venv/lib/python3.12/site-packages/discord/ext/commands/hybrid.py", line 444, in _invoke_with_namespace
    value = await self._do_call(ctx, ctx.kwargs)  # type: ignore
            ^^^^^^^^^^^^^^^^^^^^^^^^^^^^^^^^^^^^
  File "/home/abc/Desktop/Coding/Python/Discord Bot/Skybot/.venv/lib/python3.12/site-packages/discord/app_commands/commands.py", line 876, in _do_call
    raise CommandInvokeError(self, e) from e
discord.app_commands.errors.CommandInvokeError: Command 'rank' raised an exception: OperationalError: no such column: level

The above exception was the direct cause of the following exception:

Traceback (most recent call last):
  File "/home/abc/Desktop/Coding/Python/Discord Bot/Skybot/.venv/lib/python3.12/site-packages/discord/ext/commands/hybrid.py", line 444, in _invoke_with_namespace
    value = await self._do_call(ctx, ctx.kwargs)  # type: ignore
            ^^^^^^^^^^^^^^^^^^^^^^^^^^^^^^^^^^^^
  File "/home/abc/Desktop/Coding/Python/Discord Bot/Skybot/.venv/lib/python3.12/site-packages/discord/app_commands/commands.py", line 876, in _do_call
    raise CommandInvokeError(self, e) from e
discord.ext.commands.errors.HybridCommandError: Hybrid command raised an error: Command 'rank' raised an exception: OperationalError: no such column: level
ERROR      - 2024-09-13 18:22:39 - bot             : Ignoring exception in command rank
Traceback (most recent call last):
  File "/home/abc/Desktop/Coding/Python/Discord Bot/Skybot/.venv/lib/python3.12/site-packages/discord/app_commands/commands.py", line 857, in _do_call
    return await self._callback(self.binding, interaction, **params)  # type: ignore
           ^^^^^^^^^^^^^^^^^^^^^^^^^^^^^^^^^^^^^^^^^^^^^^^^^^^^^^^^^
  File "/home/abc/Desktop/Coding/Python/Discord Bot/Skybot/cogs/Level.py", line 148, in rank
    exp, level, rank = result
    ^^^^^^^^^^^^^^^^
TypeError: cannot unpack non-iterable NoneType object

The above exception was the direct cause of the following exception:

Traceback (most recent call last):
  File "/home/abc/Desktop/Coding/Python/Discord Bot/Skybot/.venv/lib/python3.12/site-packages/discord/ext/commands/hybrid.py", line 444, in _invoke_with_namespace
    value = await self._do_call(ctx, ctx.kwargs)  # type: ignore
            ^^^^^^^^^^^^^^^^^^^^^^^^^^^^^^^^^^^^
  File "/home/abc/Desktop/Coding/Python/Discord Bot/Skybot/.venv/lib/python3.12/site-packages/discord/app_commands/commands.py", line 872, in _do_call
    raise CommandInvokeError(self, e) from e
discord.app_commands.errors.CommandInvokeError: Command 'rank' raised an exception: TypeError: cannot unpack non-iterable NoneType object

The above exception was the direct cause of the following exception:

Traceback (most recent call last):
  File "/home/abc/Desktop/Coding/Python/Discord Bot/Skybot/.venv/lib/python3.12/site-packages/discord/ext/commands/hybrid.py", line 444, in _invoke_with_namespace
    value = await self._do_call(ctx, ctx.kwargs)  # type: ignore
            ^^^^^^^^^^^^^^^^^^^^^^^^^^^^^^^^^^^^
  File "/home/abc/Desktop/Coding/Python/Discord Bot/Skybot/.venv/lib/python3.12/site-packages/discord/app_commands/commands.py", line 872, in _do_call
    raise CommandInvokeError(self, e) from e
discord.ext.commands.errors.HybridCommandError: Hybrid command raised an error: Command 'rank' raised an exception: TypeError: cannot unpack non-iterable NoneType object
ERROR      - 2024-09-13 18:22:51 - client          : Ignoring exception in on_message
Traceback (most recent call last):
  File "/home/abc/Desktop/Coding/Python/Discord Bot/Skybot/.venv/lib/python3.12/site-packages/discord/client.py", line 449, in _run_event
    await coro(*args, **kwargs)
  File "/home/abc/Desktop/Coding/Python/Discord Bot/Skybot/cogs/Level.py", line 101, in on_message
    try: exp, last_level =  fetch_user_info(message)
                            ^^^^^^^^^^^^^^^^^^^^^^^^
  File "/home/abc/Desktop/Coding/Python/Discord Bot/Skybot/cogs/Level.py", line 33, in fetch_user_info
    cursor.execute(f"""
sqlite3.OperationalError: table Level has 4 columns but 3 values were supplied
ERROR      - 2024-09-13 18:22:52 - client          : Ignoring exception in on_message
Traceback (most recent call last):
  File "/home/abc/Desktop/Coding/Python/Discord Bot/Skybot/.venv/lib/python3.12/site-packages/discord/client.py", line 449, in _run_event
    await coro(*args, **kwargs)
  File "/home/abc/Desktop/Coding/Python/Discord Bot/Skybot/cogs/Level.py", line 101, in on_message
    try: exp, last_level =  fetch_user_info(message)
                            ^^^^^^^^^^^^^^^^^^^^^^^^
  File "/home/abc/Desktop/Coding/Python/Discord Bot/Skybot/cogs/Level.py", line 33, in fetch_user_info
    cursor.execute(f"""
sqlite3.OperationalError: table Level has 4 columns but 3 values were supplied
ERROR      - 2024-09-13 18:22:52 - client          : Ignoring exception in on_message
Traceback (most recent call last):
  File "/home/abc/Desktop/Coding/Python/Discord Bot/Skybot/.venv/lib/python3.12/site-packages/discord/client.py", line 449, in _run_event
    await coro(*args, **kwargs)
  File "/home/abc/Desktop/Coding/Python/Discord Bot/Skybot/cogs/Level.py", line 101, in on_message
    try: exp, last_level =  fetch_user_info(message)
                            ^^^^^^^^^^^^^^^^^^^^^^^^
  File "/home/abc/Desktop/Coding/Python/Discord Bot/Skybot/cogs/Level.py", line 33, in fetch_user_info
    cursor.execute(f"""
sqlite3.OperationalError: table Level has 4 columns but 3 values were supplied
ERROR      - 2024-09-13 18:23:26 - client          : Ignoring exception in on_message
Traceback (most recent call last):
  File "/home/abc/Desktop/Coding/Python/Discord Bot/Skybot/.venv/lib/python3.12/site-packages/discord/client.py", line 449, in _run_event
    await coro(*args, **kwargs)
  File "/home/abc/Desktop/Coding/Python/Discord Bot/Skybot/cogs/Level.py", line 101, in on_message
    try: exp, last_level =  fetch_user_info(message)
                            ^^^^^^^^^^^^^^^^^^^^^^^^
  File "/home/abc/Desktop/Coding/Python/Discord Bot/Skybot/cogs/Level.py", line 33, in fetch_user_info
    cursor.execute(f"""
sqlite3.OperationalError: table Level has 4 columns but 3 values were supplied
ERROR      - 2024-09-13 18:23:42 - client          : Ignoring exception in on_message
Traceback (most recent call last):
  File "/home/abc/Desktop/Coding/Python/Discord Bot/Skybot/.venv/lib/python3.12/site-packages/discord/client.py", line 449, in _run_event
    await coro(*args, **kwargs)
  File "/home/abc/Desktop/Coding/Python/Discord Bot/Skybot/cogs/Level.py", line 101, in on_message
    try: exp, last_level =  fetch_user_info(message)
                            ^^^^^^^^^^^^^^^^^^^^^^^^
  File "/home/abc/Desktop/Coding/Python/Discord Bot/Skybot/cogs/Level.py", line 33, in fetch_user_info
    cursor.execute(f"""
sqlite3.OperationalError: table Level has 4 columns but 3 values were supplied
ERROR      - 2024-09-13 18:24:52 - client          : Ignoring exception in on_message
Traceback (most recent call last):
  File "/home/abc/Desktop/Coding/Python/Discord Bot/Skybot/.venv/lib/python3.12/site-packages/discord/client.py", line 449, in _run_event
    await coro(*args, **kwargs)
  File "/home/abc/Desktop/Coding/Python/Discord Bot/Skybot/cogs/Level.py", line 104, in on_message
    level = 0.1 * sqrt(exp)
                       ^^^
UnboundLocalError: cannot access local variable 'exp' where it is not associated with a value
ERROR      - 2024-09-13 18:26:15 - client          : Ignoring exception in on_message
Traceback (most recent call last):
  File "/home/abc/Desktop/Coding/Python/Discord Bot/Skybot/.venv/lib/python3.12/site-packages/discord/client.py", line 449, in _run_event
    await coro(*args, **kwargs)
  File "/home/abc/Desktop/Coding/Python/Discord Bot/Skybot/cogs/Level.py", line 104, in on_message
    level = 0.1 * sqrt(exp)
                       ^^^
UnboundLocalError: cannot access local variable 'exp' where it is not associated with a value
ERROR      - 2024-09-13 18:30:07 - client          : Ignoring exception in on_message
Traceback (most recent call last):
  File "/home/abc/Desktop/Coding/Python/Discord Bot/Skybot/.venv/lib/python3.12/site-packages/discord/client.py", line 449, in _run_event
    await coro(*args, **kwargs)
  File "/home/abc/Desktop/Coding/Python/Discord Bot/Skybot/cogs/Level.py", line 104, in on_message
    level = 0.1 * sqrt(exp)
                       ^^^
UnboundLocalError: cannot access local variable 'exp' where it is not associated with a value
ERROR      - 2024-09-13 18:33:22 - client          : Ignoring exception in on_message
Traceback (most recent call last):
  File "/home/abc/Desktop/Coding/Python/Discord Bot/Skybot/.venv/lib/python3.12/site-packages/discord/client.py", line 449, in _run_event
    await coro(*args, **kwargs)
  File "/home/abc/Desktop/Coding/Python/Discord Bot/Skybot/cogs/Level.py", line 98, in on_message
    exp, level, last_level =  fetch_user_info(message)
                              ^^^^^^^^^^^^^^^^^^^^^^^^
  File "/home/abc/Desktop/Coding/Python/Discord Bot/Skybot/cogs/Level.py", line 37, in fetch_user_info
    return result[1], result[2], result[3]
           ~~~~~~^^^
TypeError: 'NoneType' object is not subscriptable
ERROR      - 2024-09-13 18:33:46 - client          : Ignoring exception in on_message
Traceback (most recent call last):
  File "/home/abc/Desktop/Coding/Python/Discord Bot/Skybot/.venv/lib/python3.12/site-packages/discord/client.py", line 449, in _run_event
    await coro(*args, **kwargs)
  File "/home/abc/Desktop/Coding/Python/Discord Bot/Skybot/cogs/Level.py", line 116, in on_message
    await self.BOT_CMD_CHANNEL.send(embed=embed)
          ^^^^^^^^^^^^^^^^^^^^^^^^^
AttributeError: 'NoneType' object has no attribute 'send'
ERROR      - 2024-09-13 18:33:47 - client          : Ignoring exception in on_message
Traceback (most recent call last):
  File "/home/abc/Desktop/Coding/Python/Discord Bot/Skybot/.venv/lib/python3.12/site-packages/discord/client.py", line 449, in _run_event
    await coro(*args, **kwargs)
  File "/home/abc/Desktop/Coding/Python/Discord Bot/Skybot/cogs/Level.py", line 116, in on_message
    await self.BOT_CMD_CHANNEL.send(embed=embed)
          ^^^^^^^^^^^^^^^^^^^^^^^^^
AttributeError: 'NoneType' object has no attribute 'send'
ERROR      - 2024-09-13 18:33:47 - client          : Ignoring exception in on_message
Traceback (most recent call last):
  File "/home/abc/Desktop/Coding/Python/Discord Bot/Skybot/.venv/lib/python3.12/site-packages/discord/client.py", line 449, in _run_event
    await coro(*args, **kwargs)
  File "/home/abc/Desktop/Coding/Python/Discord Bot/Skybot/cogs/Level.py", line 116, in on_message
    await self.BOT_CMD_CHANNEL.send(embed=embed)
          ^^^^^^^^^^^^^^^^^^^^^^^^^
AttributeError: 'NoneType' object has no attribute 'send'
ERROR      - 2024-09-13 18:33:48 - client          : Ignoring exception in on_message
Traceback (most recent call last):
  File "/home/abc/Desktop/Coding/Python/Discord Bot/Skybot/.venv/lib/python3.12/site-packages/discord/client.py", line 449, in _run_event
    await coro(*args, **kwargs)
  File "/home/abc/Desktop/Coding/Python/Discord Bot/Skybot/cogs/Level.py", line 116, in on_message
    await self.BOT_CMD_CHANNEL.send(embed=embed)
          ^^^^^^^^^^^^^^^^^^^^^^^^^
AttributeError: 'NoneType' object has no attribute 'send'
ERROR      - 2024-09-13 18:33:48 - client          : Ignoring exception in on_message
Traceback (most recent call last):
  File "/home/abc/Desktop/Coding/Python/Discord Bot/Skybot/.venv/lib/python3.12/site-packages/discord/client.py", line 449, in _run_event
    await coro(*args, **kwargs)
  File "/home/abc/Desktop/Coding/Python/Discord Bot/Skybot/cogs/Level.py", line 116, in on_message
    await self.BOT_CMD_CHANNEL.send(embed=embed)
          ^^^^^^^^^^^^^^^^^^^^^^^^^
AttributeError: 'NoneType' object has no attribute 'send'
ERROR      - 2024-09-13 18:33:49 - client          : Ignoring exception in on_message
Traceback (most recent call last):
  File "/home/abc/Desktop/Coding/Python/Discord Bot/Skybot/.venv/lib/python3.12/site-packages/discord/client.py", line 449, in _run_event
    await coro(*args, **kwargs)
  File "/home/abc/Desktop/Coding/Python/Discord Bot/Skybot/cogs/Level.py", line 116, in on_message
    await self.BOT_CMD_CHANNEL.send(embed=embed)
          ^^^^^^^^^^^^^^^^^^^^^^^^^
AttributeError: 'NoneType' object has no attribute 'send'
ERROR      - 2024-09-13 18:33:49 - client          : Ignoring exception in on_message
Traceback (most recent call last):
  File "/home/abc/Desktop/Coding/Python/Discord Bot/Skybot/.venv/lib/python3.12/site-packages/discord/client.py", line 449, in _run_event
    await coro(*args, **kwargs)
  File "/home/abc/Desktop/Coding/Python/Discord Bot/Skybot/cogs/Level.py", line 116, in on_message
    await self.BOT_CMD_CHANNEL.send(embed=embed)
          ^^^^^^^^^^^^^^^^^^^^^^^^^
AttributeError: 'NoneType' object has no attribute 'send'
ERROR      - 2024-09-13 18:33:50 - client          : Ignoring exception in on_message
Traceback (most recent call last):
  File "/home/abc/Desktop/Coding/Python/Discord Bot/Skybot/.venv/lib/python3.12/site-packages/discord/client.py", line 449, in _run_event
    await coro(*args, **kwargs)
  File "/home/abc/Desktop/Coding/Python/Discord Bot/Skybot/cogs/Level.py", line 116, in on_message
    await self.BOT_CMD_CHANNEL.send(embed=embed)
          ^^^^^^^^^^^^^^^^^^^^^^^^^
AttributeError: 'NoneType' object has no attribute 'send'
ERROR      - 2024-09-13 18:33:51 - client          : Ignoring exception in on_message
Traceback (most recent call last):
  File "/home/abc/Desktop/Coding/Python/Discord Bot/Skybot/.venv/lib/python3.12/site-packages/discord/client.py", line 449, in _run_event
    await coro(*args, **kwargs)
  File "/home/abc/Desktop/Coding/Python/Discord Bot/Skybot/cogs/Level.py", line 116, in on_message
    await self.BOT_CMD_CHANNEL.send(embed=embed)
          ^^^^^^^^^^^^^^^^^^^^^^^^^
AttributeError: 'NoneType' object has no attribute 'send'
ERROR      - 2024-09-13 18:33:55 - client          : Ignoring exception in on_message
Traceback (most recent call last):
  File "/home/abc/Desktop/Coding/Python/Discord Bot/Skybot/.venv/lib/python3.12/site-packages/discord/client.py", line 449, in _run_event
    await coro(*args, **kwargs)
  File "/home/abc/Desktop/Coding/Python/Discord Bot/Skybot/cogs/Level.py", line 116, in on_message
    await self.BOT_CMD_CHANNEL.send(embed=embed)
          ^^^^^^^^^^^^^^^^^^^^^^^^^
AttributeError: 'NoneType' object has no attribute 'send'
ERROR      - 2024-09-13 18:34:04 - client          : Ignoring exception in on_message
Traceback (most recent call last):
  File "/home/abc/Desktop/Coding/Python/Discord Bot/Skybot/.venv/lib/python3.12/site-packages/discord/client.py", line 449, in _run_event
    await coro(*args, **kwargs)
  File "/home/abc/Desktop/Coding/Python/Discord Bot/Skybot/cogs/Level.py", line 116, in on_message
    await self.BOT_CMD_CHANNEL.send(embed=embed)
          ^^^^^^^^^^^^^^^^^^^^^^^^^
AttributeError: 'NoneType' object has no attribute 'send'
ERROR      - 2024-09-13 18:34:05 - client          : Ignoring exception in on_message
Traceback (most recent call last):
  File "/home/abc/Desktop/Coding/Python/Discord Bot/Skybot/.venv/lib/python3.12/site-packages/discord/client.py", line 449, in _run_event
    await coro(*args, **kwargs)
  File "/home/abc/Desktop/Coding/Python/Discord Bot/Skybot/cogs/Level.py", line 116, in on_message
    await self.BOT_CMD_CHANNEL.send(embed=embed)
          ^^^^^^^^^^^^^^^^^^^^^^^^^
AttributeError: 'NoneType' object has no attribute 'send'
ERROR      - 2024-09-13 18:34:20 - client          : Ignoring exception in on_message
Traceback (most recent call last):
  File "/home/abc/Desktop/Coding/Python/Discord Bot/Skybot/.venv/lib/python3.12/site-packages/discord/client.py", line 449, in _run_event
    await coro(*args, **kwargs)
  File "/home/abc/Desktop/Coding/Python/Discord Bot/Skybot/cogs/Level.py", line 116, in on_message
    await self.BOT_CMD_CHANNEL.send(embed=embed)
          ^^^^^^^^^^^^^^^^^^^^^^^^^
AttributeError: 'NoneType' object has no attribute 'send'
