INFO       - 2024-09-09 12:43:38 - client          : logging in using static token
INFO       - 2024-09-09 12:43:39 - gateway         : Shard ID None has connected to Gateway (Session ID: 36d9d2356ab4f17bcc335dcc0996b688).
ERROR      - 2024-09-09 12:43:42 - client          : Ignoring exception in on_message
Traceback (most recent call last):
  File "/home/dcadmin/Desktop/Main/Skybot/.venv/lib/python3.12/site-packages/discord/client.py", line 449, in _run_event
    await coro(*args, **kwargs)
  File "/home/dcadmin/Desktop/Main/Skybot/cogs/Level.py", line 100, in on_message
    exp, last_level =  fetch_user_info(message)
                       ^^^^^^^^^^^^^^^^^^^^^^^^
  File "/home/dcadmin/Desktop/Main/Skybot/cogs/Level.py", line 33, in fetch_user_info
    cursor.execute(f"""
sqlite3.OperationalError: table Level has 4 columns but 3 values were supplied
ERROR      - 2024-09-09 12:43:54 - client          : Ignoring exception in on_message
Traceback (most recent call last):
  File "/home/dcadmin/Desktop/Main/Skybot/.venv/lib/python3.12/site-packages/discord/client.py", line 449, in _run_event
    await coro(*args, **kwargs)
  File "/home/dcadmin/Desktop/Main/Skybot/cogs/Level.py", line 100, in on_message
    exp, last_level =  fetch_user_info(message)
                       ^^^^^^^^^^^^^^^^^^^^^^^^
  File "/home/dcadmin/Desktop/Main/Skybot/cogs/Level.py", line 33, in fetch_user_info
    cursor.execute(f"""
sqlite3.OperationalError: table Level has 4 columns but 3 values were supplied
ERROR      - 2024-09-09 12:43:54 - bot             : Ignoring exception in command trophy
Traceback (most recent call last):
  File "/home/dcadmin/Desktop/Main/Skybot/.venv/lib/python3.12/site-packages/discord/app_commands/commands.py", line 857, in _do_call
    return await self._callback(self.binding, interaction, **params)  # type: ignore
           ^^^^^^^^^^^^^^^^^^^^^^^^^^^^^^^^^^^^^^^^^^^^^^^^^^^^^^^^^
  File "/home/dcadmin/Desktop/Main/Skybot/cogs/Fishing.py", line 44, in trophy
    await ctx.send(embed=embed)
  File "/home/dcadmin/Desktop/Main/Skybot/.venv/lib/python3.12/site-packages/discord/ext/commands/context.py", line 1077, in send
    await self.interaction.response.send_message(**kwargs)
  File "/home/dcadmin/Desktop/Main/Skybot/.venv/lib/python3.12/site-packages/discord/interactions.py", line 855, in send_message
    await adapter.create_interaction_response(
  File "/home/dcadmin/Desktop/Main/Skybot/.venv/lib/python3.12/site-packages/discord/webhook/async_.py", line 221, in request
    raise NotFound(response, data)
discord.errors.NotFound: 404 Not Found (error code: 10062): Unknown interaction

The above exception was the direct cause of the following exception:

Traceback (most recent call last):
  File "/home/dcadmin/Desktop/Main/Skybot/.venv/lib/python3.12/site-packages/discord/ext/commands/hybrid.py", line 444, in _invoke_with_namespace
    value = await self._do_call(ctx, ctx.kwargs)  # type: ignore
            ^^^^^^^^^^^^^^^^^^^^^^^^^^^^^^^^^^^^
  File "/home/dcadmin/Desktop/Main/Skybot/.venv/lib/python3.12/site-packages/discord/app_commands/commands.py", line 876, in _do_call
    raise CommandInvokeError(self, e) from e
discord.app_commands.errors.CommandInvokeError: Command 'trophy' raised an exception: NotFound: 404 Not Found (error code: 10062): Unknown interaction

The above exception was the direct cause of the following exception:

Traceback (most recent call last):
  File "/home/dcadmin/Desktop/Main/Skybot/.venv/lib/python3.12/site-packages/discord/ext/commands/hybrid.py", line 444, in _invoke_with_namespace
    value = await self._do_call(ctx, ctx.kwargs)  # type: ignore
            ^^^^^^^^^^^^^^^^^^^^^^^^^^^^^^^^^^^^
  File "/home/dcadmin/Desktop/Main/Skybot/.venv/lib/python3.12/site-packages/discord/app_commands/commands.py", line 876, in _do_call
    raise CommandInvokeError(self, e) from e
discord.ext.commands.errors.HybridCommandError: Hybrid command raised an error: Command 'trophy' raised an exception: NotFound: 404 Not Found (error code: 10062): Unknown interaction
ERROR      - 2024-09-09 12:43:59 - client          : Ignoring exception in on_message
Traceback (most recent call last):
  File "/home/dcadmin/Desktop/Main/Skybot/.venv/lib/python3.12/site-packages/discord/client.py", line 449, in _run_event
    await coro(*args, **kwargs)
  File "/home/dcadmin/Desktop/Main/Skybot/cogs/Level.py", line 102, in on_message
    if level > last_level:
       ^^^^^
UnboundLocalError: cannot access local variable 'level' where it is not associated with a value
ERROR      - 2024-09-09 12:44:04 - client          : Ignoring exception in on_message
Traceback (most recent call last):
  File "/home/dcadmin/Desktop/Main/Skybot/.venv/lib/python3.12/site-packages/discord/client.py", line 449, in _run_event
    await coro(*args, **kwargs)
  File "/home/dcadmin/Desktop/Main/Skybot/cogs/Level.py", line 102, in on_message
    if level > last_level:
       ^^^^^
UnboundLocalError: cannot access local variable 'level' where it is not associated with a value
ERROR      - 2024-09-09 12:44:07 - client          : Ignoring exception in on_message
Traceback (most recent call last):
  File "/home/dcadmin/Desktop/Main/Skybot/.venv/lib/python3.12/site-packages/discord/client.py", line 449, in _run_event
    await coro(*args, **kwargs)
  File "/home/dcadmin/Desktop/Main/Skybot/cogs/Level.py", line 100, in on_message
    exp, last_level =  fetch_user_info(message)
                       ^^^^^^^^^^^^^^^^^^^^^^^^
  File "/home/dcadmin/Desktop/Main/Skybot/cogs/Level.py", line 33, in fetch_user_info
    cursor.execute(f"""
sqlite3.OperationalError: table Level has 4 columns but 3 values were supplied
ERROR      - 2024-09-09 12:44:18 - client          : Ignoring exception in on_message
Traceback (most recent call last):
  File "/home/dcadmin/Desktop/Main/Skybot/.venv/lib/python3.12/site-packages/discord/client.py", line 449, in _run_event
    await coro(*args, **kwargs)
  File "/home/dcadmin/Desktop/Main/Skybot/cogs/Level.py", line 100, in on_message
    exp, last_level =  fetch_user_info(message)
                       ^^^^^^^^^^^^^^^^^^^^^^^^
  File "/home/dcadmin/Desktop/Main/Skybot/cogs/Level.py", line 33, in fetch_user_info
    cursor.execute(f"""
sqlite3.OperationalError: table Level has 4 columns but 3 values were supplied
ERROR      - 2024-09-09 12:44:22 - client          : Ignoring exception in on_message
Traceback (most recent call last):
  File "/home/dcadmin/Desktop/Main/Skybot/.venv/lib/python3.12/site-packages/discord/client.py", line 449, in _run_event
    await coro(*args, **kwargs)
  File "/home/dcadmin/Desktop/Main/Skybot/cogs/Level.py", line 100, in on_message
    exp, last_level =  fetch_user_info(message)
                       ^^^^^^^^^^^^^^^^^^^^^^^^
  File "/home/dcadmin/Desktop/Main/Skybot/cogs/Level.py", line 33, in fetch_user_info
    cursor.execute(f"""
sqlite3.OperationalError: table Level has 4 columns but 3 values were supplied
ERROR      - 2024-09-09 12:44:24 - client          : Ignoring exception in on_message
Traceback (most recent call last):
  File "/home/dcadmin/Desktop/Main/Skybot/.venv/lib/python3.12/site-packages/discord/client.py", line 449, in _run_event
    await coro(*args, **kwargs)
  File "/home/dcadmin/Desktop/Main/Skybot/cogs/Level.py", line 100, in on_message
    exp, last_level =  fetch_user_info(message)
                       ^^^^^^^^^^^^^^^^^^^^^^^^
  File "/home/dcadmin/Desktop/Main/Skybot/cogs/Level.py", line 33, in fetch_user_info
    cursor.execute(f"""
sqlite3.OperationalError: table Level has 4 columns but 3 values were supplied
ERROR      - 2024-09-09 12:44:34 - client          : Ignoring exception in on_message
Traceback (most recent call last):
  File "/home/dcadmin/Desktop/Main/Skybot/.venv/lib/python3.12/site-packages/discord/client.py", line 449, in _run_event
    await coro(*args, **kwargs)
  File "/home/dcadmin/Desktop/Main/Skybot/cogs/Level.py", line 100, in on_message
    exp, last_level =  fetch_user_info(message)
                       ^^^^^^^^^^^^^^^^^^^^^^^^
  File "/home/dcadmin/Desktop/Main/Skybot/cogs/Level.py", line 33, in fetch_user_info
    cursor.execute(f"""
sqlite3.OperationalError: table Level has 4 columns but 3 values were supplied
